Workbook
Name cats: FunFacts[fact_category]

Sheet funfacts-draft
A1: fact_id | B1: fact | C1: fact_details | D1: fact_source | E1: created_at | F1: fact_category | G1: fact_img
A2: 04e58638-5f23-4eb5-bc79-7bad041e2dee | B2: A group of frogs is called an army. | D2: https://www.hachette.co.uk/wp-content/uploads/2019/06/hbg-title-9780762473144-67.pdf | F2: Animal Facts, Werd Facts
A3: 05fa46eb-5139-44c6-9127-dfad75db4565 | B3: In Switzerland, it is illegal to own only one guinea pig. | C3: It's considered animal abuse, because they're social beings and get lonely. | D3: https://blogs.loc.gov/law/2021/01/laws-involving-animals-real-and-mythical | F3: Animal Facts, Weird Laws, Places & Cultures
A4: 0648ab41-b83b-4bbc-bee0-404cb1fe6469 | B4: The unicorn is Scotland’s national animal, reportedly chosen for its associations with dominance, chivalry, purity, and innocence in Celtic mythology. | C4: The mythical animal has been a celebrated symbol for centuries, appearing on the Scottish royal coat of arms in the 12th century and on gold coins in the 1600s. In Celtic mythology, the unicorn represents purity, innocence and power. National Unicorn Day is celebrated annually on April 9 to honor the unicorn and its cultural, historical, and symbolic significance. | D4: https://www.nts.org.uk/stories/the-unicorn-scotlands-national-animal | F4: Places & Cultures, Animal Facts | G4: https://www.theheraldrysociety.com/wp-content/uploads/2018/03/Royal-Arms-of-Scotland-2-1200x600.jpg
A5: 08546c25-55d4-46fe-ab7b-ca8141da023b | B5: The world’s shortest commercial flight operates in Scotland. The 1.7-mile journey takes about 90 seconds. | C5: Loganair’s Westray Airfield <--> Papa Westray Airfield route (about 90 seconds). | D5: https://edition.cnn.com/travel/article/worlds-shortest-flight-orkney-scotland | F5: Places & Cultures | G5: https://pbs.twimg.com/media/G0tXMmqXwAAOKVL.jpg
A6: 098210f5-0627-4d43-964c-05438b9c03fa | B6: Some cats are allergic to humans. | D6: https://articles.hepper.com/could-your-cat-be-allergic-to-you/ | F6: Animal Facts, Health & Medicine
A7: 12d6f0db-64ed-4436-befe-08aaf1ab597f | B7: Ironically, the fear of long words is called hippopotomonstrosesquipedaliophobia. The 36-letter term was first used in the first century BCE to criticize writers with an excessive fondness for long words. | D7: https://www.verywellmind.com/hippopotomonstrosesquipedaliophobia-2671752 | F7: Werd Facts, Mind & Behavior
A8: 13992a48-ef48-49d4-9c76-d62295c650b8 | B8: In Japan, you can buy square watermelons. | C8: Known as Shikaku Suika in Japanese, they are just regular watermelons that are, instead, cube-shaped. | D8: https://japanesetaste.com/blogs/japanese-taste-blog/all-about-japan-s-square-shaped-watermelons?redirectedFrom=int | F8: Places & Cultures
A9: 1668b69c-e777-40df-b13b-22fe6a790c07 | B9: The high school set from iCarly was also used in Saved by the Bell and That’s So Raven, which may explain why it looks familiar. | C9: Similarly, the town of Rosewood in Pretty Little Liars was repurposed from Stars Hollow, originally built for Gilmore Girls. | D9: https://www.cracked.com/article_46000_tv-show-sets-that-were-recycled-for-other-series.html | F9: Pop Culture | G9: a9yE3YW_700b.jpg (700×467)
A10: 1e3e8293-39ad-445d-ab28-43a8511f64fa | B10: Cows can walk up stairs, but they cannot easily walk back down them. | D10: https://iere.org/why-cant-cows-walk-downstairs/ | F10: Animal Facts
A11: 2a2f6bfb-b6ab-4ef2-a57f-ef3753741026 | B11: If Earth’s history were condensed into 24 hours, life would appear at 4:00 a.m., land plants at 10:24 p.m., the dinosaurs would go extinct at 11:41 p.m., and human history would begin at 11:58:43 p.m. | D11: https://funfactz.com/science/earth-history-condensed | F11: Science
A12: 2ba8130a-7b1d-4242-9cbe-74da2380c688 | B12: The hazelnut is Oregon’s official state nut. | D12: https://www.oregon.gov/oda/about-us/Pages/oregon-symbols.aspx | F12: Places & Cultures
A13: 30019e16-dcbb-47b9-9f52-04521f6c7f29 | B13: Heating two capfuls of pure vanilla extract in an oven-safe container at 300 degrees for an hour can make your home smell like vanilla within about 20 minutes. | D13: https://www.apartmenttherapy.com/use-vanilla-extract-to-make-you-152035 | F13: Life Hacks
A14: 32f7dbc9-29a5-4350-8a7e-89127342a8e3 | B14: The word "Triskaidekaphobia" is commonly used in spelling bees. | D14: https://www.merriam-webster.com/dictionary/triskaidekaphobia | F14: Werd Facts
A15: 3a99c78a-a85b-41bd-be76-70a218c66d82 | B15: At the end of the Beatles’ song “A Day in the Life,” there is a high-frequency sound that only dogs can hear. | C15: The Beatles added a 15 kHz high frequency tone as a playful Easter egg. | D15: https://workingpawstraining.com/tips-for-owners/f/theres-a-beatles-song-that-has-a-frequency-only-dogs-can-hear | F15: Pop Culture, Animal Facts
A16: 3dbec4bb-12dc-4f03-92ff-daad01f3c982 | B16: Kim Kardashian reportedly has a “glam clause” in her will stating that if she cannot get ready or communicate for herself, someone must ensure that her hair, nails, and makeup look perfect. | D16: https://www.usmagazine.com/stylish/news/kim-kardashians-will-has-hair-makeup-nail-clause-details/ | F16: Pop Culture
A17: 4343caea-26e0-4db5-8e7c-e5866265ed80 | B17: Exercise and spending time with pets can both help support mental well-being and ease symptoms of depression. | D17: https://www.nature.com/articles/s41380-022-01819-w | F17: Mind & Behavior, Animal Facts, Health & Medicine
A18: 4714770b-2c4a-4750-91cc-4ab4049491c6 | B18: When spelled out, no number from one to 999 contains the letter “a.” | D18: https://interestingfacts.com/fact/no-number-before-1000-contains-letter-a/ | F18: Werd Facts
A19: 4efd4589-9c81-423a-a15f-38ff6d8f491c | B19: A team of six women programmed the first general-purpose electronic digital computer. | C19: ENIAC programmers Kay McNulty, Betty Jennings, Betty Snyder, Marlyn Wescoff, Fran Bilas, Ruth Lichterman. | D19: https://spectrum.ieee.org/the-women-behind-eniac | F19: Inventions & Technology, Science
A20: 5470c343-a960-48cb-a0e3-1466ed8ac3c0 | B20: According to Genesis 1:20–22, the chicken came before the egg. | D20: https://thefactbase.com/according-to-genesis-1-20-22-the-chicken-came-before-the-egg/ | F20: Science, Animal Facts
A21: 57d845dc-5d6e-43cf-b0d4-e6140862b0ad | B21: Dr. Seuss wrote Green Eggs and Ham as the result of a bet. | C21: Dr. Seuss said he wrote it after Bennett Cerf bet he couldn’t write a book using only 50 words. | D21: https://library.osu.edu/site/40stories/2022/04/06/the-bet-that-led-to-green-eggs-and-ham/ | F21: Pop Culture
A22: 5c32884c-98c9-4157-a81c-bbce3a314e9c | B22: Rats can laugh, especially when they are tickled. | D22: https://www.newscientist.com/article/2385124-rats-have-a-laugh-centre-in-their-brains-that-responds-to-tickling/ | F22: Animal Facts, Science
A23: 5c37920d-d6cb-462c-bb80-abf9c7240356 | B23: Harry Styles has four nipples due to a common condition called polythelia. | D23: https://www.allure.com/story/harry-styles-confirms-he-has-four-nipples | F23: Pop Culture, Health & Medicine
A24: 63af974e-8bf1-4a76-b52e-af57ac9c7cb3 | B24: Early chainsaw-like tools were developed in late-18th-century Scotland to assist with symphysiotomies and the removal of diseased bone during childbirth. | D24: https://www.iflscience.com/we-regret-to-inform-you-that-chainsaws-were-originally-invented-for-childbirth-58685 | F24: Health & Medicine, History & Society, Inventions & Technology
A25: 698bc7f3-ad99-43a2-a868-accb1adf4a0b | B25: Your shadow always points directly toward the center of a rainbow. | D25: https://www.natgeokids.com/nz/discover/science/nature/science-dr-karl-rainbow/ | F25: Science
A26: 75dc6ebc-830b-40c2-81aa-7d72a12f1ae2 | B26: The word “run” is said to have more definitions than any other English word, with as many as 645 meanings. | D26: https://www.mentalfloss.com/article/582820/run-most-complex-word-in-english-language | F26: Werd Facts
A27: 7e751146-3f12-4ff5-96de-f6b26a2348aa | B27: Under certain circumstances, French law allows a person to marry someone who has died. | D27: https://en.wikipedia.org/wiki/Posthumous_marriage_in_France | F27: Weird Laws, Places & Cultures
A28: 896cb3fd-c11f-4362-a85e-4c72566789c6 | B28: Nutmeg contains myristicin, a natural compound that can cause hallucinogenic effects when consumed in large doses. | D28: https://tripsitter.com/psychedelics/natural/page/5/ | F28: Science
A29: 9829ed12-0c04-46d7-ba31-f99c5fb24295 | B29: A jiffy is an actual unit of time equal to one-hundredth of a second. | D29: https://www.sciencefocus.com/science/how-long-is-a-jiffy | F29: Werd Facts, Science
A30: a3fffc81-893c-4ae9-9630-44ead8270ab8 | B30: Cows can form close bonds with “best friends” and may become stressed when separated from them. | D30: https://buzztatler.com/do-cows-have-best-friends-heres-what-science-says/ | F30: Animal Facts
A31: b2bdeb2b-24bb-4f23-9526-f44d3eb13a49 | B31: People once said “prunes” instead of “cheese” when posing for photographs. | C31: In the 1840s, a cheesy grin was seen as childish, so a London photographer told people to say "prunes" to keep their mouths tight. | D31: https://www.getty.edu/news/why-didnt-people-smile-in-old-photos/ | F31: History & Society, Werd Facts
A32: bc26fcfd-fb88-4f0b-9ec7-163fdc2bc000 | B32: A group of bunnies is called a “fluffle.” | C32: Informally* | D32: https://rabbit.org/care/collective-nouns/ | F32: Animal Facts, Werd Facts
A33: bc76adaa-5c18-4331-a9a2-c89cf5e378c2 | B33: One study claimed that the average woman can keep a secret for 47 hours and 15 minutes. | D33: https://thefactbase.com/the-average-amount-of-time-a-woman-can-keep-a-secret-is-47-hours-and-15-minutes/ | F33: Mind & Behavior
A34: bdd33f3b-2c81-4b31-ac47-d91c4dad168a | B34: Russi Taylor and Wayne Allwine, the actors who voiced Minnie and Mickey Mouse, married in real life in 1991. | D34: https://www.thedisneyclassics.com/blog/mickey-and-minnie | F34: Pop Culture
A35: be0814d4-6a01-4007-9f2b-20bcd7f893f4 | B35: The way we view others may reflect our own traits: positive perceptions can reveal positive qualities, while negative perceptions can reveal negative ones. | D35: https://www.sciencedaily.com/releases/2010/08/100802165441.htm | F35: Mind & Behavior
A36: c8d40f9a-80ae-4e7b-8b52-28a53b1f9945 | B36: Finland has been ranked the world’s happiest country for seven consecutive years. | D36: https://worldpopulationreview.com/country-rankings/happiest-countries-in-the-world | F36: Places & Cultures, Mind & Behavior
A37: c9333ec7-5ebb-4680-a0fc-d421aa708ffc | B37: Africa is the only continent located in all four hemispheres. | C37: Africa crosses the Equator and the Prime Meridian. | D37: https://www.geographyrealm.com/continent-four-hemispheres/ | F37: Places & Cultures
A38: d209799c-fbb5-4436-b5a3-3877c98e4402 | B38: All clownfish are born male and can become female later in life. | D38: https://australian.museum/learn/teachers/learning/sleek-geeks-videos/sex-change-in-clownfish/ | F38: Animal Facts, Science
A39: e211b29f-7b6e-45c2-b056-8cfdae894dfd | B39: You can remember the digits of pi by counting the letters in each word of the phrase, “May I have a large container of coffee?” | D39: https://math.hmc.edu/funfacts/memorizing-pi/ | F39: Werd Facts, Science, Life Hacks
B40: In ancient Greece, throwing an apple at someone was a way to declare your love. | D40: https://classicalanthology.theclassicslibrary.com/2017/03/28/the-apple-of-love/ | F40: History & Society, Places & Cultures
...

Sheet Categories
C1: Fact Category | D1: Fact Count
A2: History & Society | C2: =A2 -> History & Society | D2: {=SUMPRODUCT(--ISNUMBER(SEARCH(","&C2&",",","&SUBSTITUTE('funfacts-draft'!$F$2:$F$86,", ",",")&",")))} -> 14
A3: Health & Medicine | C3: =A3 -> Health & Medicine | D3: {=SUMPRODUCT(--ISNUMBER(SEARCH(","&C3&",",","&SUBSTITUTE('funfacts-draft'!$F$2:$F$86,", ",",")&",")))} -> 10
A4: Places & Cultures | C4: =A4 -> Places & Cultures | D4: {=SUMPRODUCT(--ISNUMBER(SEARCH(","&C4&",",","&SUBSTITUTE('funfacts-draft'!$F$2:$F$86,", ",",")&",")))} -> 19
A5: Werd Facts | C5: =A5 -> Werd Facts | D5: {=SUMPRODUCT(--ISNUMBER(SEARCH(","&C5&",",","&SUBSTITUTE('funfacts-draft'!$F$2:$F$86,", ",",")&",")))} -> 17
A6: Animal Facts | C6: =A6 -> Animal Facts | D6: {=SUMPRODUCT(--ISNUMBER(SEARCH(","&C6&",",","&SUBSTITUTE('funfacts-draft'!$F$2:$F$86,", ",",")&",")))} -> 16
A7: Weird Laws | C7: =A7 -> Weird Laws | D7: {=SUMPRODUCT(--ISNUMBER(SEARCH(","&C7&",",","&SUBSTITUTE('funfacts-draft'!$F$2:$F$86,", ",",")&",")))} -> 6
A8: Life Hacks | C8: =A8 -> Life Hacks | D8: {=SUMPRODUCT(--ISNUMBER(SEARCH(","&C8&",",","&SUBSTITUTE('funfacts-draft'!$F$2:$F$86,", ",",")&",")))} -> 6
A9: Mind & Behavior | C9: =A9 -> Mind & Behavior | D9: {=SUMPRODUCT(--ISNUMBER(SEARCH(","&C9&",",","&SUBSTITUTE('funfacts-draft'!$F$2:$F$86,", ",",")&",")))} -> 12
A10: Science | C10: =A10 -> Science | D10: {=SUMPRODUCT(--ISNUMBER(SEARCH(","&C10&",",","&SUBSTITUTE('funfacts-draft'!$F$2:$F$86,", ",",")&",")))} -> 12
A11: Inventions & Technology | C11: =A11 -> Inventions & Technology | D11: {=SUMPRODUCT(--ISNUMBER(SEARCH(","&C11&",",","&SUBSTITUTE('funfacts-draft'!$F$2:$F$86,", ",",")&",")))} -> 2
A12: Pop Culture | C12: =A12 -> Pop Culture | D12: {=SUMPRODUCT(--ISNUMBER(SEARCH(","&C12&",",","&SUBSTITUTE('funfacts-draft'!$F$2:$F$86,", ",",")&",")))} -> 18

Sheet notes
A1: removed all weird law facts at the bottom of the list. I don't want illegitimate facts
